<?xml version="1.0" encoding="UTF-8"?>
<!-- Generated by org.testng.reporters.JUnitXMLReporter -->
<testsuite hostname="CaoNhan-PC" name="Default test" tests="10" failures="1" timestamp="26 Sep 2016 12:53:39 GMT" time="0.975" errors="0">
  <testcase name="deleteEmployee" time="0.042" classname="com.gcs.serp_qtdh.controller.AppControllerTest"/>
  <testcase name="editEmployee" time="0.056" classname="com.gcs.serp_qtdh.controller.AppControllerTest"/>
  <testcase name="listEmployees" time="0.003" classname="com.gcs.serp_qtdh.controller.AppControllerTest">
    <failure type="java.lang.AssertionError" message="expected [allemployees] but found [login]">
      <![CDATA[java.lang.AssertionError: expected [allemployees] but found [login]
	at org.testng.Assert.fail(Assert.java:94)
	at org.testng.Assert.failNotEquals(Assert.java:496)
	at org.testng.Assert.assertEquals(Assert.java:125)
	at org.testng.Assert.assertEquals(Assert.java:178)
	at org.testng.Assert.assertEquals(Assert.java:188)
	at com.gcs.serp_qtdh.controller.AppControllerTest.listEmployees(AppControllerTest.java:61)
	at sun.reflect.NativeMethodAccessorImpl.invoke0(Native Method)
	at sun.reflect.NativeMethodAccessorImpl.invoke(Unknown Source)
	at sun.reflect.DelegatingMethodAccessorImpl.invoke(Unknown Source)
	at java.lang.reflect.Method.invoke(Unknown Source)
	at org.testng.internal.MethodInvocationHelper.invokeMethod(MethodInvocationHelper.java:85)
	at org.testng.internal.Invoker.invokeMethod(Invoker.java:659)
	at org.testng.internal.Invoker.invokeTestMethod(Invoker.java:845)
	at org.testng.internal.Invoker.invokeTestMethods(Invoker.java:1153)
	at org.testng.internal.TestMethodWorker.invokeTestMethods(TestMethodWorker.java:125)
	at org.testng.internal.TestMethodWorker.run(TestMethodWorker.java:108)
	at org.testng.TestRunner.privateRun(TestRunner.java:771)
	at org.testng.TestRunner.run(TestRunner.java:621)
	at org.testng.SuiteRunner.runTest(SuiteRunner.java:357)
	at org.testng.SuiteRunner.runSequentially(SuiteRunner.java:352)
	at org.testng.SuiteRunner.privateRun(SuiteRunner.java:310)
	at org.testng.SuiteRunner.run(SuiteRunner.java:259)
	at org.testng.SuiteRunnerWorker.runSuite(SuiteRunnerWorker.java:52)
	at org.testng.SuiteRunnerWorker.run(SuiteRunnerWorker.java:86)
	at org.testng.TestNG.runSuitesSequentially(TestNG.java:1199)
	at org.testng.TestNG.runSuitesLocally(TestNG.java:1124)
	at org.testng.TestNG.run(TestNG.java:1032)
	at org.testng.remote.RemoteTestNG.run(RemoteTestNG.java:111)
	at org.testng.remote.RemoteTestNG.initAndRun(RemoteTestNG.java:204)
	at org.testng.remote.RemoteTestNG.main(RemoteTestNG.java:175)
]]>
    </failure>
  </testcase> <!-- listEmployees -->
  <testcase name="newEmployee" time="0.003" classname="com.gcs.serp_qtdh.controller.AppControllerTest"/>
  <testcase name="saveEmployeeWithSuccess" time="0.003" classname="com.gcs.serp_qtdh.controller.AppControllerTest"/>
  <testcase name="saveEmployeeWithValidationError" time="0.005" classname="com.gcs.serp_qtdh.controller.AppControllerTest"/>
  <testcase name="saveEmployeeWithValidationErrorNonUniqueSSN" time="0.046" classname="com.gcs.serp_qtdh.controller.AppControllerTest"/>
  <testcase name="updateEmployeeWithSuccess" time="0.005" classname="com.gcs.serp_qtdh.controller.AppControllerTest"/>
  <testcase name="updateEmployeeWithValidationError" time="0.002" classname="com.gcs.serp_qtdh.controller.AppControllerTest"/>
  <testcase name="updateEmployeeWithValidationErrorNonUniqueSSN" time="0.002" classname="com.gcs.serp_qtdh.controller.AppControllerTest"/>
</testsuite> <!-- Default test -->
